Workbook

Sheet Read me
A1: Read me
A2: Card placement proposal (2026-10-15). A design proposal only: nothing in canonical/cards.json or the map data was changed.
A3: Which enemy cards belong on which map, Maps 0-21 and their side maps, theme first, then the skill curriculum, then rarity.
A4: Map 0 "today" means your published Map 0 decks (Pond Patrol, Thicket Swarm, 0-3, 0-4). Other maps use the repo map data. Raid-boss fights are left out.
A5: Roles: map-specific = the map's own natives; biome = shared by maps of that biome; shared basic = the basic 10 and starters; elite-boss only = only in the elite or boss deck; submap unique = met only on that side map; reused = seen earlier on the road.
A6: Fights: "(x1 rare spawn)" means one copy only, as a surprise in a regular skirmish. Fight counts follow 4 (Map 0) to 9 (Map 19), 11 on Map 20, 9 on Map 21.
A7: "(new)" rows are cards that do not exist yet (Gannet, Puffin, Peregrine, Archerfish, Chough Flock, Kestrel).
A8: Notes mark sheet changes this plan would need later (rarity relabels, a skill to add). None were made.
A9: Play order puts The Old Bramble after The Ice Hollow, since it unlocks there.
A10: Blue numbers on "Skirmish rarity curve" are design targets you can edit; the totals and every count on "Cards per map count" are formulas.
A11: Sheets: Placement, Skirmish rarity curve, Skill curriculum (thematic), Cards per map count, Biome supply vs need, Babies & eggs.

Sheet Placement
A1: Order | B1: Map | C1: Map name | D1: Biome | E1: Card id | F1: Name | G1: Rarity (sheet) | H1: Skills | I1: Role | J1: Fights | K1: Change vs today | L1: First meeting on the road? | M1: In packs? | N1: Road maps it is on | O1: Notes
A2: 1 | B2: Map 0 side | C2: Tutorial | D2: Forest edge | E2: honey-bee | F2: Honey Bee | G2: Starter | H2: Flying | I2: shared basic | J2: Tutorial; Tutorial II; T-2; T-4 | K2: moved from Basalt Foundry (Map 19 side), Map 7, Map 8, The Mycelium Deep (Map 7 side); also stays on Clovermead (Map 1 side), Map 0 | L2: Yes | M2: No | N2: 3 | O2: Flying. Base bees do not swarm.
A3: 1 | B3: Map 0 side | C3: Tutorial | D3: Forest edge | E3: pond-duck | F3: Pond Duck | G3: Starter | H3: (none) | I3: shared basic | J3: Tutorial; T-2 | K3: moved from The Old Bramble (Map 0 side); also stays on Lilypad Reach (Map 2 side), Map 0 | L3: Yes | M3: No | N3: 3
A4: 1 | B4: Map 0 side | C4: Tutorial | D4: Forest edge | E4: cottontail | F4: Cottontail | G4: Starter | H4: (none) | I4: shared basic | J4: Tutorial II; T-3 | K4: moved from Map 15; also stays on Clovermead (Map 1 side), Map 0 | L4: Yes | M4: No | N4: 3
A5: 1 | B5: Map 0 side | C5: Tutorial | D5: Forest edge | E5: pond-trout | F5: Pond Trout | G5: Starter | H5: (none) | I5: shared basic | J5: Tutorial; T-3 | K5: already here | L5: Yes | M5: No | N5: 3 | O5: Fish carry Tide, which reads "?" until Map 2.
A6: 1 | B6: Map 0 side | C6: Tutorial | D6: Forest edge | E6: meadow-frog | F6: Meadow Frog | G6: Common | H6: (none) | I6: shared basic | J6: Tutorial II; T-2 | K6: moved from Clovermead (Map 1 side); also stays on Map 0, Map 1 | L6: Yes | M6: No | N6: 4
A7: 1 | B7: Map 0 side | C7: Tutorial | D7: Forest edge | E7: crossed-eyes | F7: Crossed-Eyes | G7: Starter | H7: (none) | I7: shared basic | J7: T-2; T-4 | K7: new here (also stays on Map 0, Map 3) | L7: Yes | M7: No | N7: 3
A8: 1 | B8: Map 0 side | C8: Tutorial | D8: Forest edge | E8: garden-snail | F8: Garden Snail | G8: Starter | H8: Armor 1 | I8: shared basic | J8: Tutorial II; T-4 | K8: moved from The Mycelium Deep (Map 7 side); also stays on Clovermead (Map 1 side), Map 0, Map 7 | L8: Yes | M8: No | N8: 4
A9: 1 | B9: Map 0 side | C9: Tutorial | D9: Forest edge | E9: meadow-rabbit | F9: Meadow Rabbit | G9: Starter | H9: (none) | I9: shared basic | J9: Tutorial; T-3; T-4 | K9: already here | L9: Yes | M9: No | N9: 3
A10: 1 | B10: Map 0 side | C10: Tutorial | D10: Forest edge | E10: acorn-chipmunk | F10: Acorn Chipmunk | G10: Starter | H10: (none) | I10: shared basic | J10: T-2; T-4 | K10: new here (also stays on Map 0) | L10: Yes | M10: No | N10: 2
A11: 1 | B11: Map 0 side | C11: Tutorial | D11: Forest edge | E11: chipmunk-forager | F11: Chipmunk Forager | G11: Starter | H11: (none) | I11: shared basic | J11: Tutorial; Tutorial II | K11: moved from Clovermead (Map 1 side), Map 17; also stays on Map 0 | L11: Yes | M11: No | N11: 2
A12: 1 | B12: Map 0 side | C12: Tutorial | D12: Forest edge | E12: ant-scout | F12: Ant Scout | G12: Starter | H12: Swarm | I12: shared basic | J12: T-3 | K12: already here | L12: Yes | M12: No | N12: 2 | O12: T-3 keeps its ant line: the Swarm preview.
A13: 1 | B13: Map 0 side | C13: Tutorial | D13: Forest edge | E13: worker-ant | F13: Worker Ant | G13: Starter | H13: trigger:onAttack | I13: shared basic | J13: T-3 | K13: already here | L13: Yes | M13: No | N13: 2
A14: 2 | B14: Map 0 | C14: Bramblewood Outskirts | D14: Forest edge | E14: honey-bee | F14: Honey Bee | G14: Starter | H14: Flying | I14: shared basic | J14: 0-1 Pond Patrol; 0-3 Raccoon Heist; 0-4 Fox Den (boss) | K14: already here | L14: No | M14: No | N14: 3 | O14: Flying is taught here (base bees: no Swarm).
A15: 2 | B15: Map 0 | C15: Bramblewood Outskirts | D15: Forest edge | E15: pond-duck | F15: Pond Duck | G15: Starter | H15: (none) | I15: shared basic | J15: 0-1 Pond Patrol; 0-4 Fox Den (boss) | K15: already here | L15: No | M15: No | N15: 3
A16: 2 | B16: Map 0 | C16: Bramblewood Outskirts | D16: Forest edge | E16: cottontail | F16: Cottontail | G16: Starter | H16: (none) | I16: shared basic | J16: 0-1 Pond Patrol; 0-3 Raccoon Heist | K16: already here | L16: No | M16: No | N16: 3
A17: 2 | B17: Map 0 | C17: Bramblewood Outskirts | D17: Forest edge | E17: pond-trout | F17: Pond Trout | G17: Starter | H17: (none) | I17: shared basic | J17: 0-1 Pond Patrol; 0-2 Ant Line | K17: already here | L17: No | M17: No | N17: 3
A18: 2 | B18: Map 0 | C18: Bramblewood Outskirts | D18: Forest edge | E18: meadow-frog | F18: Meadow Frog | G18: Common | H18: (none) | I18: shared basic | J18: 0-1 Pond Patrol; 0-2 Ant Line | K18: already here | L18: No | M18: No | N18: 4
A19: 2 | B19: Map 0 | C19: Bramblewood Outskirts | D19: Forest edge | E19: crossed-eyes | F19: Crossed-Eyes | G19: Starter | H19: (none) | I19: shared basic | J19: 0-1 Pond Patrol; 0-4 Fox Den (boss) | K19: already here | L19: No | M19: No | N19: 3
A20: 2 | B20: Map 0 | C20: Bramblewood Outskirts | D20: Forest edge | E20: garden-snail | F20: Garden Snail | G20: Starter | H20: Armor 1 | I20: shared basic | J20: 0-1 Pond Patrol; 0-2 Ant Line | K20: already here | L20: No | M20: No | N20: 4 | O20: Armor 1 is a soft preview; Map 1 teaches Armor properly.
A21: 2 | B21: Map 0 | C21: Bramblewood Outskirts | D21: Forest edge | E21: meadow-rabbit | F21: Meadow Rabbit | G21: Starter | H21: (none) | I21: shared basic | J21: 0-1 Pond Patrol; 0-3 Raccoon Heist | K21: already here | L21: No | M21: No | N21: 3
A22: 2 | B22: Map 0 | C22: Bramblewood Outskirts | D22: Forest edge | E22: acorn-chipmunk | F22: Acorn Chipmunk | G22: Starter | H22: (none) | I22: shared basic | J22: 0-1 Pond Patrol; 0-3 Raccoon Heist; 0-4 Fox Den (boss) | K22: already here | L22: No | M22: No | N22: 2
A23: 2 | B23: Map 0 | C23: Bramblewood Outskirts | D23: Forest edge | E23: chipmunk-forager | F23: Chipmunk Forager | G23: Starter | H23: (none) | I23: shared basic | J23: 0-1 Pond Patrol; 0-4 Fox Den (boss) | K23: already here | L23: No | M23: No | N23: 2
A24: 2 | B24: Map 0 | C24: Bramblewood Outskirts | D24: Forest edge | E24: ant-scout | F24: Ant Scout | G24: Starter | H24: Swarm | I24: map-specific | J24: 0-2 Ant Line; 0-4 Fox Den (boss) | K24: already here | L24: No | M24: No | N24: 2 | O24: Swarm, on ants only. 0-2 is all ants plus a few basics, and weak on purpose.
A25: 2 | B25: Map 0 | C25: Bramblewood Outskirts | D25: Forest edge | E25: worker-ant | F25: Worker Ant | G25: Starter | H25: trigger:onAttack | I25: map-specific | J25: 0-2 Ant Line | K25: already here | L25: No | M25: No | N25: 2
A26: 2 | B26: Map 0 | C26: Bramblewood Outskirts | D26: Forest edge | E26: forager-ant | F26: Forager Ant | G26: Common | H26: trigger:onAttack | I26: map-specific | J26: 0-2 Ant Line | K26: already here | L26: Yes | M26: No | N26: 1
A27: 2 | B27: Map 0 | C27: Bramblewood Outskirts | D27: Forest edge | E27: earthworm | F27: Earthworm | G27: Starter | H27: Regeneration 1 (pending) | I27: map-specific | J27: 0-2 Ant Line; 0-4 Fox Den (boss) | K27: new here (on no map today) | L27: Yes | M27: No | N27: 2 | O27: Regeneration lives here. Sheet change needed: give Earthworm Regen 1.
A28: 2 | B28: Map 0 | C28: Bramblewood Outskirts | D28: Forest edge | E28: trash-panda-trickster | F28: Trash Panda Trickster | G28: Common | H28: Worthy 1, Nocturnal | I28: map-specific | J28: 0-3 Raccoon Heist; 0-4 Fox Den (boss) | K28: already here | L28: Yes | M28: Yes | N28: 3 | O28: Nocturnal reads "?" in the mist.
A29: 2 | B29: Map 0 | C29: Bramblewood Outskirts | D29: Forest edge | E29: chipmunk-skirmisher | F29: Chipmunk Skirmisher | G29: Common | H29: (none) | I29: map-specific | J29: 0-3 Raccoon Heist | K29: already here | L29: Yes | M29: No | N29: 1
A30: 2 | B30: Map 0 | C30: Bramblewood Outskirts | D30: Forest edge | E30: smoke-raccoon | F30: Smokescreen Raccoon | G30: Uncommon | H30: Smoke Bomb | I30: map-specific | J30: 0-3 Raccoon Heist | K30: new here (on no map today) | L30: Yes | M30: No | N30: 3 | O30: The ONE uncommon of 0-3 (x2): the heist's getaway Smoke Bomb. Replaces Fleetfoot'd, which leaks Quick and Tide.
A31: 2 | B31: Map 0 | C31: Bramblewood Outskirts | D31: Forest edge | E31: fox-kit | F31: Fox Kit | G31: Rare | H31: (none) | I31: elite-boss only | J31: 0-4 Fox Den (boss) | K31: already here | L31: Yes | M31: No | N31: 2 | O31: The ONE new uncommon of 0-4 (x2), leading into Sergeant Bramblefox. Sheet says Rare: relabel to Uncommon.
A32: 3 | B32: Map 1 | C32: Thistlewood | D32: Hedgerow & meadow | E32: hedgehog-scout | F32: Hedgehog Scout | G32: Common | H32: Thorns 1 | I32: map-specific | J32: 1-1; 1-2; 1-4; 1-5 (boss) | K32: already here | L32: Yes | M32: No | N32: 2 | O32: Thorns is taught here.
A33: 3 | B33: Map 1 | C33: Thistlewood | D33: Hedgerow & meadow | E33: beetle-grunt | F33: Beetle Grunt | G33: Common | H33: Armor 1 | I33: map-specific | J33: 1-1; 1-3; 1-5 (boss) | K33: already here | L33: Yes | M33: No | N33: 1 | O33: Armor is taught here (the beetle's 1 Armor; crabs repeat it on Map 2).
A34: 3 | B34: Map 1 | C34: Thistlewood | D34: Hedgerow & meadow | E34: clover-butterfly | F34: Clover Butterfly | G34: Common | H34: Flying, Diurnal | I34: map-specific | J34: 1-1; 1-2; 1-4 | K34: new here (on no map today) | L34: Yes | M34: No | N34: 2 | O34: Diurnal is taught here: the first card that wakes with the sun.
A35: 3 | B35: Map 1 | C35: Thistlewood | D35: Hedgerow & meadow | E35: dormouse | F35: Dormouse | G35: Common | H35: (none) | I35: map-specific | J35: 1-1; 1-3 | K35: already here | L35: Yes | M35: No | N35: 1
A36: 3 | B36: Map 1 | C36: Thistlewood | D36: Hedgerow & meadow | E36: cricket-drummer | F36: Cricket Drummer | G36: Common | H36: (none) | I36: map-specific | J36: 1-2; 1-3 | K36: already here | L36: Yes | M36: No | N36: 1
A37: 3 | B37: Map 1 | C37: Thistlewood | D37: Hedgerow & meadow | E37: field-crow | F37: Field Crow | G37: Common | H37: Flying, Diurnal (pending) | I37: biome | J37: 1-2; 1-3 | K37: new here (on no map today) | L37: Yes | M37: No | N37: 1 | O37: Sheet change suggested: Diurnal, so Map 1 has two Diurnal natives.
A38: 3 | B38: Map 1 | C38: Thistlewood | D38: Hedgerow & meadow | E38: field-mouse | F38: Field Mouse | G38: Common | H38: Worthy 1 | I38: biome | J38: 1-1; 1-4 | K38: already here | L38: Yes | M38: No | N38: 2
A39: 3 | B39: Map 1 | C39: Thistlewood | D39: Hedgerow & meadow | E39: pill-bug | F39: Pill Bug | G39: Uncommon | H39: Armor 1 | I39: biome | J39: 1-3 | K39: new here (also stays on Clovermead (Map 1 side)) | L39: Yes | M39: No | N39: 2 | O39: Second Armor body.
A40: 3 | B40: Map 1 | C40: Thistlewood | D40: Hedgerow & meadow | E40: inside-out-hedgehog | F40: Inside-Out Hedgehog | G40: Uncommon | H40: Armor 2, Thorns 1 | I40: biome | J40: 1-4 | K40: new here (on no map today) | L40: Yes | M40: Yes | N40: 1 | O40: Pack uncommon seen in the hedge before it is sold (Armor + Thorns).
...

Sheet Skirmish rarity curve
A1: Map | B1: Fights (proposed) | C1: Regular: Common (incl. Starter) | D1: Regular: Uncommon | E1: Regular: Rare | F1: Regular: Very / Super rare | G1: Regular: Epic | H1: Regular: Heroic / Unique | I1: Regular: Total | J1: Elite: Common | K1: Elite: Uncommon | L1: Elite: Rare | M1: Elite: Very / Super rare | N1: Elite: Epic | O1: Elite: Heroic / Unique | P1: Elite: Total | Q1: Boss: Common | R1: Boss: Uncommon | S1: Boss: Rare | T1: Boss: Very / Super rare | U1: Boss: Epic | V1: Boss: Heroic / Unique | W1: Boss: Total | X1: Notes
A2: Map 0 | B2: 4 | C2: 20 | D2: 0 | E2: 0 | F2: 0 | G2: 0 | H2: 0 | I2: =SUM(C2:H2) -> 20 | P2: no elite | Q2: 16 | R2: 4 | S2: 0 | T2: 0 | U2: 0 | V2: 0 | W2: =SUM(Q2:V2) -> 20 | X2: 0-1 and 0-2 all common (0-2 is the weak ant line). 0-3: 18 common + 2 of ONE uncommon (Smokescreen Raccoon). 0-4 boss: 16 common + the 0-3 uncommon + ONE new uncommon (Fox Kit).
A3: Map 1 | B3: 5 | C3: 18 | D3: 2 | E3: 0 | F3: 0 | G3: 0 | H3: 0 | I3: =SUM(C3:H3) -> 20 | P3: no elite | Q3: 13 | R3: 4 | S3: 2 | T3: 0 | U3: 0 | V3: 1 | W3: =SUM(Q3:V3) -> 20 | X3: From here the last fight is the boss and gets the rarity pass: one heroic (the boss card) and two rares.
A4: Map 2 | B4: 5 | C4: 16 | D4: 3 | E4: 1 | F4: 0 | G4: 0 | H4: 0 | I4: =SUM(C4:H4) -> 20 | P4: no elite | Q4: 12 | R4: 5 | S4: 2 | T4: 0 | U4: 0 | V4: 1 | W4: =SUM(Q4:V4) -> 20 | X4: First rare spawn: one copy of a rare, in one regular fight only (Pelican Diver in 2-4).
A5: Map 3 | B5: 6 | C5: 16 | D5: 3 | E5: 1 | F5: 0 | G5: 0 | H5: 0 | I5: =SUM(C5:H5) -> 20 | P5: no elite | Q5: 12 | R5: 5 | S5: 2 | T5: 0 | U5: 0 | V5: 1 | W5: =SUM(Q5:V5) -> 20
A6: Map 4 | B6: 6 | C6: 16 | D6: 3 | E6: 1 | F6: 0 | G6: 0 | H6: 0 | I6: =SUM(C6:H6) -> 20 | J6: 13 | K6: 4 | L6: 3 | M6: 0 | N6: 0 | O6: 0 | P6: =SUM(J6:O6) -> 20 | Q6: 12 | R6: 5 | S6: 2 | T6: 0 | U6: 0 | V6: 1 | W6: =SUM(Q6:V6) -> 20 | X6: First mid-map elite (the fight before the boss).
A7: Map 5 | B7: 6 | C7: 15 | D7: 4 | E7: 1 | F7: 0 | G7: 0 | H7: 0 | I7: =SUM(C7:H7) -> 20 | J7: 12 | K7: 5 | L7: 3 | M7: 0 | N7: 0 | O7: 0 | P7: =SUM(J7:O7) -> 20 | Q7: 10 | R7: 6 | S7: 3 | T7: 0 | U7: 0 | V7: 1 | W7: =SUM(Q7:V7) -> 20
A8: Map 6 | B8: 6 | C8: 15 | D8: 4 | E8: 1 | F8: 0 | G8: 0 | H8: 0 | I8: =SUM(C8:H8) -> 20 | J8: 12 | K8: 5 | L8: 3 | M8: 0 | N8: 0 | O8: 0 | P8: =SUM(J8:O8) -> 20 | Q8: 10 | R8: 6 | S8: 3 | T8: 0 | U8: 0 | V8: 1 | W8: =SUM(Q8:V8) -> 20
A9: Map 7 | B9: 6 | C9: 15 | D9: 4 | E9: 1 | F9: 0 | G9: 0 | H9: 0 | I9: =SUM(C9:H9) -> 20 | J9: 12 | K9: 5 | L9: 3 | M9: 0 | N9: 0 | O9: 0 | P9: =SUM(J9:O9) -> 20 | Q9: 10 | R9: 6 | S9: 3 | T9: 0 | U9: 0 | V9: 1 | W9: =SUM(Q9:V9) -> 20
A10: Map 8 | B10: 7 | C10: 14 | D10: 5 | E10: 1 | F10: 0 | G10: 0 | H10: 0 | I10: =SUM(C10:H10) -> 20 | J10: 11 | K10: 6 | L10: 3 | M10: 0 | N10: 0 | O10: 0 | P10: =SUM(J10:O10) -> 20 | Q10: 8 | R10: 7 | S10: 3 | T10: 1 | U10: 0 | V10: 1 | W10: =SUM(Q10:V10) -> 20
A11: Map 9 | B11: 7 | C11: 14 | D11: 5 | E11: 1 | F11: 0 | G11: 0 | H11: 0 | I11: =SUM(C11:H11) -> 20 | J11: 11 | K11: 6 | L11: 3 | M11: 0 | N11: 0 | O11: 0 | P11: =SUM(J11:O11) -> 20 | Q11: 8 | R11: 7 | S11: 3 | T11: 1 | U11: 0 | V11: 1 | W11: =SUM(Q11:V11) -> 20
A12: Map 10 | B12: 7 | C12: 13 | D12: 5 | E12: 2 | F12: 0 | G12: 0 | H12: 0 | I12: =SUM(C12:H12) -> 20 | J12: 9 | K12: 6 | L12: 4 | M12: 1 | N12: 0 | O12: 0 | P12: =SUM(J12:O12) -> 20 | Q12: 7 | R12: 7 | S12: 4 | T12: 1 | U12: 0 | V12: 1 | W12: =SUM(Q12:V12) -> 20 | X12: Regular fights now carry two rares; elites add a very rare.
A13: Map 11 | B13: 7 | C13: 12 | D13: 6 | E13: 2 | F13: 0 | G13: 0 | H13: 0 | I13: =SUM(C13:H13) -> 20 | J13: 8 | K13: 7 | L13: 4 | M13: 1 | N13: 0 | O13: 0 | P13: =SUM(J13:O13) -> 20 | Q13: 6 | R13: 8 | S13: 4 | T13: 1 | U13: 0 | V13: 1 | W13: =SUM(Q13:V13) -> 20
A14: Map 12 | B14: 7 | C14: 12 | D14: 6 | E14: 2 | F14: 0 | G14: 0 | H14: 0 | I14: =SUM(C14:H14) -> 20 | J14: 8 | K14: 7 | L14: 4 | M14: 1 | N14: 0 | O14: 0 | P14: =SUM(J14:O14) -> 20 | Q14: 6 | R14: 8 | S14: 4 | T14: 1 | U14: 0 | V14: 1 | W14: =SUM(Q14:V14) -> 20
A15: Map 13 | B15: 8 | C15: 12 | D15: 6 | E15: 2 | F15: 0 | G15: 0 | H15: 0 | I15: =SUM(C15:H15) -> 20 | J15: 8 | K15: 7 | L15: 4 | M15: 1 | N15: 0 | O15: 0 | P15: =SUM(J15:O15) -> 20 | Q15: 6 | R15: 8 | S15: 4 | T15: 1 | U15: 0 | V15: 1 | W15: =SUM(Q15:V15) -> 20
A16: Map 14 | B16: 8 | C16: 11 | D16: 7 | E16: 2 | F16: 0 | G16: 0 | H16: 0 | I16: =SUM(C16:H16) -> 20 | J16: 7 | K16: 8 | L16: 4 | M16: 1 | N16: 0 | O16: 0 | P16: =SUM(J16:O16) -> 20 | Q16: 6 | R16: 8 | S16: 4 | T16: 1 | U16: 0 | V16: 1 | W16: =SUM(Q16:V16) -> 20
A17: Map 15 | B17: 8 | C17: 11 | D17: 7 | E17: 2 | F17: 0 | G17: 0 | H17: 0 | I17: =SUM(C17:H17) -> 20 | J17: 7 | K17: 8 | L17: 4 | M17: 1 | N17: 0 | O17: 0 | P17: =SUM(J17:O17) -> 20 | Q17: 5 | R17: 8 | S17: 5 | T17: 1 | U17: 0 | V17: 1 | W17: =SUM(Q17:V17) -> 20
A18: Map 16 | B18: 8 | C18: 10 | D18: 7 | E18: 3 | F18: 0 | G18: 0 | H18: 0 | I18: =SUM(C18:H18) -> 20 | J18: 6 | K18: 8 | L18: 5 | M18: 1 | N18: 0 | O18: 0 | P18: =SUM(J18:O18) -> 20 | Q18: 4 | R18: 8 | S18: 5 | T18: 2 | U18: 0 | V18: 1 | W18: =SUM(Q18:V18) -> 20 | X18: Three rares per regular fight: still 9-11 commons, so pack commons stay the backbone.
A19: Map 17 | B19: 8 | C19: 9 | D19: 8 | E19: 3 | F19: 0 | G19: 0 | H19: 0 | I19: =SUM(C19:H19) -> 20 | J19: 5 | K19: 9 | L19: 5 | M19: 1 | N19: 0 | O19: 0 | P19: =SUM(J19:O19) -> 20 | Q19: 4 | R19: 8 | S19: 5 | T19: 2 | U19: 0 | V19: 1 | W19: =SUM(Q19:V19) -> 20
A20: Map 18 | B20: 9 | C20: 9 | D20: 8 | E20: 3 | F20: 0 | G20: 0 | H20: 0 | I20: =SUM(C20:H20) -> 20 | J20: 5 | K20: 9 | L20: 5 | M20: 1 | N20: 0 | O20: 0 | P20: =SUM(J20:O20) -> 20 | Q20: 4 | R20: 8 | S20: 5 | T20: 2 | U20: 0 | V20: 1 | W20: =SUM(Q20:V20) -> 20
A21: Map 19 | B21: 9 | C21: 9 | D21: 8 | E21: 3 | F21: 0 | G21: 0 | H21: 0 | I21: =SUM(C21:H21) -> 20 | J21: 5 | K21: 9 | L21: 5 | M21: 1 | N21: 0 | O21: 0 | P21: =SUM(J21:O21) -> 20 | Q21: 4 | R21: 8 | S21: 5 | T21: 2 | U21: 0 | V21: 1 | W21: =SUM(Q21:V21) -> 20
A22: Map 20 | B22: 11 | C22: 7 | D22: 9 | E22: 3 | F22: 1 | G22: 0 | H22: 0 | I22: =SUM(C22:H22) -> 20 | J22: 3 | K22: 10 | L22: 5 | M22: 2 | N22: 0 | O22: 0 | P22: =SUM(J22:O22) -> 20 | Q22: 2 | R22: 8 | S22: 6 | T22: 2 | U22: 1 | V22: 1 | W22: =SUM(Q22:V22) -> 20 | X22: Final approach: one very rare in regular fights; the final boss is the unique Triumvirate.
A23: Map 21 | B23: 9 | C23: 9 | D23: 8 | E23: 3 | F23: 0 | G23: 0 | H23: 0 | I23: =SUM(C23:H23) -> 20 | J23: 5 | K23: 9 | L23: 5 | M23: 1 | N23: 0 | O23: 0 | P23: =SUM(J23:O23) -> 20 | Q23: 3 | R23: 8 | S23: 6 | T23: 2 | U23: 0 | V23: 1 | W23: =SUM(Q23:V23) -> 20 | X23: A breather: the Map 19 mix, before 20-40 gets harder.
A24: Map 30 | B24: 10 | C24: 7 | D24: 8 | E24: 4 | F24: 1 | G24: 0 | H24: 0 | I24: =SUM(C24:H24) -> 20 | J24: 4 | K24: 8 | L24: 5 | M24: 2 | N24: 1 | O24: 0 | P24: =SUM(J24:O24) -> 20 | Q24: 3 | R24: 5 | S24: 7 | T24: 3 | U24: 1 | V24: 1 | W24: =SUM(Q24:V24) -> 20 | X24: Sample. Commons still a third of a regular deck.
A25: Map 40 | B25: 12 | C25: 5 | D25: 7 | E25: 6 | F25: 2 | G25: 0 | H25: 0 | I25: =SUM(C25:H25) -> 20 | J25: 2 | K25: 7 | L25: 7 | M25: 3 | N25: 1 | O25: 0 | P25: =SUM(J25:O25) -> 20 | Q25: 2 | R25: 4 | S25: 7 | T25: 4 | U25: 2 | V25: 1 | W25: =SUM(Q25:V25) -> 20 | X25: Sample. Regular: no heroic, ever. Boss: always one heroic or unique, a few rare to super rare, and a floor of commons and uncommons.
A27: Counts are cards in a 20-card deck. Blue cells are design targets (inputs); the Total columns are formulas and should all read 20. "Rare" assumes the relabels in the Placement notes (Fox Kit, Bear Cub, Stable Colt and other babies and small animals read Rare in the sheet today).

Sheet Skill curriculum (thematic)
A1: Order | B1: Map | C1: Map name | D1: Biome | E1: Native animals | F1: Skills introduced: definite | G1: Skills introduced: maybe | H1: Why it fits | I1: How it differs from the Recommended sheet | J1: Also first seen here in this placement (incidental)
A2: 1 | B2: Map 0 side | C2: Tutorial | D2: Forest edge | E2: Bees, ducks, rabbits, chipmunks, trout, frogs, snails, ants | F2: (none new) | H2: Teaches play, not skills. Basics only. | I2: Same idea; T-2 "Odd Lot" and T-4 "Final Exam" leave (17 skills shown there today). | J2: Flying, Armor, Swarm
A3: 2 | B3: Map 0 | C3: Bramblewood Outskirts | D3: Forest edge | E3: Bees, ants, earthworms, rabbits, chipmunks, ducks, trout, frogs, snails, raccoons, fox kits | F3: Flying, Swarm, Regeneration | G3: Smoke Bomb (one-off, 0-3) | H3: Bees fly, ants swarm, worms regrow. The mist hides Nocturnal and Tide as "?". | I3: Same three as your call. Adds the raccoon one-off as the 0-3 hook. Bee Sentry (Poison), Beetle Grunt (Armor), Bee Forager (bee Swarm) and Fleetfoot'd (Quick, Tide) leave Map 0. | J3: Regeneration, Worthy, Nocturnal, Smoke Bomb
A4: 3 | B4: Map 1 | C4: Thistlewood | D4: Hedgerow & meadow | E4: Hedgehogs, beetles, pill bugs, butterflies, crows, dormice, crickets, mice, badgers | F4: Diurnal, Thorns, Armor | G4: Rainrunner (the frog) | H4: Day/night starts under the first big trees; hedgehogs are thorny, beetles are armoured. | I4: Your list. Recommended had Diurnal + Nocturnal + bee Swarm here; Thorns and Armor moved down from Maps 0 side / 4. | J4: Thorns, Diurnal
A5: 4 | B5: Map 1 side | C5: Clovermead | D5: Hedgerow & meadow | E5: Rabbits, harvest mice, butterflies, pond skaters, bees | F5: (none new) | G5: Rainrunner (Puddle Skimmer) | H5: A gentle meadow: reuse plus one rain-skater. | I5: Recommended had Evasive here; Evasive now waits for the cliffs (Map 3). | J5: Rainrunner
A6: 5 | B6: Map 2 | C6: Pebble Beach | D6: Shore | E6: Crabs, gulls, pelicans, conches, sea turtles, otters, small fry | F6: Tide, Molting | G6: Swimmer, Wave, Shell (conch) | H6: Every crab already molts; the Tide is the beach. | I6: Same Tide; Molting promoted from "shown by accident" to taught. Crab Fork should become Crab Claws. | J6: Swimmer, Tide, Molting, Wave, Fork, Crab Claws, Shell, Revivificated
A7: 6 | B7: Map 2 side | C7: Lilypad Reach | D7: Freshwater | E7: Frogs, ducks, minnows, carp, trout | F7: (none new) | G7: Rainmaker | H7: A still pond: frogs and ducks you know, one rain-calling frog. The Mallard (Pounce) waits until after the cliffs. | I7: Recommended had Pounce here; Pounce moves to the cliff birds. The beaver lodge moves to Map 4. | J7: Rainmaker
A8: 7 | B8: Map 2 side | C8: Smugglers' Grotto | D8: Sea cave | E8: Smuggling raccoons, cave fish, crabs, spark flies, an octopus | F8: Darksight (with the dark field) | G8: Lantern | H8: The first pitch-black map: the natives see without light, the visitors bring lanterns. | I8: Same intent as Recommended (Darksight, Lantern), on cave natives. | J8: Cleave, Lantern, Darksight
A9: 8 | B9: Map 3 | C9: Gannet Cliffs | D9: Sea cliffs | E9: Gannets, puffins, gulls, pelicans, hawks, sea eagles, ravens, feral goats, seals | F9: Arrow, Pounce, Evasive | G9: Quick (only with a Peregrine) | H9: Birds dive (Pounce) and shoot (Arrow); goats and seals slip away (Evasive). | I9: Your list. Recommended had Arrow + Skyfall; Skyfall goes up to the mountains (Map 11). | J9: Pounce, Arrow, Evasive, Quick
A10: 9 | B10: Map 4 | C10: Sunken Hollow | D10: Freshwater lowland | E10: Beavers, lumber badgers, turtles, tortoises, herons, kingfishers, pike, carp | F10: Lumberjack, Guardian | G10: Timber, the Lumber economy | H10: The hollow is flooded because beavers dammed it: builders, lumber and a heron on guard. The Nest opens here (eggs). | I10: Recommended had Armor, Thorns, Gash, Inspiring off whales and a kraken. Whales and kraken leave for the sea. | J10: Lumberjack, onReadyGold, Guardian, Timber
A11: 10 | B11: Map 5 | C11: Gatorback Swamp | D11: Swamp | E11: Vipers, leeches, toads, caimans, snapping turtles, capybaras, alligators | F11: Poison, Bleed, Ambush | G11: Shedding, Explode | H11: Snakes bite, leeches drain, gators wait. | I11: Recommended had Poison + Ambush; Bleed added (leeches). Bee Sentry no longer leaks Poison on Map 0. | J11: Poison, Shedding, Bleed, explode, Ambush
A12: 11 | B12: Map 5 side | C12: The Sunken Grove | D12: Swamp | E12: Newts, root lurkers, swamp natives | F12: Healing | H12: Your "heal in the swamp maps". | I12: Same as Recommended. | J12: Healing
A13: 12 | B13: Map 6 | C13: Sable Swampmire | D13: Swamp (night) | E13: Gangrenous leeches, wisps, witch-herons, vampire bats, crocodiles, carcasses | F13: Fester, Remember | G13: Sap, Render | H13: The black swamp is about rot and things that come back. | I13: Recommended had Bleed + Bloom here; Bleed moved to Map 5, Bloom to the fungi. | J13: Fester, Remember, sap, Render, onDeathSpawn
A14: 13 | B14: Map 7 | C14: The Morel Hollow | D14: Fungal woodland | E14: Morels, grubs, dung beetles, bombardier beetles, moths, spiders, snails, worms | F14: Sleep, Decay | G14: Bloom (fungal), Rocket (one-off), Demolisher (the battering-ram beetle, elite), Scare (Creeper preview) | H14: Spores put you to sleep; dung beetles rot you. | I14: Same core as Recommended; Bloom moved here from Map 6. | J14: Bloom, sleep, Decay, Rocket, Scare, Demolisher
A15: 14 | B15: Map 7 side | C15: The Mycelium Deep | D15: Underground (fungal) | E15: Puffballs, web spiders, carrion flies, giant worms | F15: (none new) | G15: Brood, Earthquake (one-off) | H15: A side map: reuse plus the first walking fungus. | I15: Recommended had Darkness here; it already started in the Grotto. | J15: Brood, Earthquake
A16: 15 | B16: Map 8 | C16: Caves & Alcoves | D16: Underground | E16: Electric bats, moles, olms, centipedes, cave fish, golems | F16: Electricity, Keen Sense | G16: Stealth, Dynamite (one-off) | H16: Your electric bats live here; moles smell what they cannot see. | I16: Same as Recommended, minus Shock Bolt. | J16: Electricity, Keen Sense, Heavy Metal, onReadyDamage, Stealth, Dynamite
A17: 16 | B17: Map 8 side | C17: The Glimmer Depths | D17: Underground (crystal) | E17: Glimmer spiders, mirror moths, a malachite golem | F17: (none new) | G17: Reflect | H17: Shiny walls, shiny-loving things. | I17: Recommended had Shock; that sits better in deep water (Sunken Depths). | J17: Reflect
A18: 17 | B18: Map 9 | C18: The Kelp Mangroves | D18: Mangrove | E18: Mudskippers, monitors, kingfishers, archerfish, eels, pufferfish, cuttlefish, sea otters | F18: Quick, Reload | G18: Backstab (Wrong-Way Salmon) | H18: Mudskippers sprint; eels lunge and rest. | I18: Recommended had Wave + Molting (both already on Map 2 crabs). | J18: Reload, Backstab
A19: 18 | B19: Map 10 | C19: Coral Current | D19: Open sea | E19: Clownfish, coral, morays, reef sharks, jellies, mantas, orcas, humpbacks, narwhals | F19: Crit, Momentum, Moonpull | G19: Inspiring, Bloom (coral), Expose (narwhal elite) | H19: Sharks crit, orcas build momentum, jellies pull the tide. | I19: Recommended had Shell + Bloom; whales arrive here from Map 4 and bring their skills. | J19: Crit, Moonpull, Inspiring, Expose, Momentum
A20: 19 | B20: Map 10 side | C20: The Sunken Depths | D20: Deep sea | E20: Krakens, squid, octopus, nautilus, electric eels, barnacles | F20: Gash | G20: Corrode, Shock | H20: The deep things are old and strange. | I20: Recommended had Moonpull (now Map 10). | J20: Gash, shock, Corrode
A21: 20 | B21: Map 11 | C21: Eyrie Heights | D21: Mountain | E21: Marmots, rams, condors, vultures, choughs, kestrels, eagles, chipmunks | F21: Skyfall, Daunt, Volley | G21: Twin Shot, Lightning | H21: Vultures drop stones, wardens cow you, flocks rain arrows: the ranged family grows from Arrow. | I21: Same Volley/Twin Shot idea, but on new mountain birds (no card has these skills yet). | J21: Skyfall, Volley, Twin Shot, Daunt, Avalanche, Lightning
A22: 21 | B22: Map 11 side | C22: The Aerie Vault | D22: Mountain | E22: Ravens, eagles, condors | F22: (none new) | H22: Oldest nests: reuse plus ravens. | I22: Recommended had Snipe here; Snipe goes to the Briar Maze foxes.
A23: 22 | B23: Map 12 | C23: The Briar Maze | D23: Hedgerow (briar) | E23: Changelings, rabbits, hedgehogs, porcupines, foxes, sapper mice and badgers | F23: Keen Eye, Changeling, Twin Strike | G23: Snipe, Backstab, Twin (Puddle Changeling) | H23: A maze that lies: changelings, and the scouts that see through them. | I23: Recommended had Cleave + Expose; Changeling and Keen Eye belong together. | J23: Changeling, Keen Eye, Twin Strike, Snipe, Twin
A24: 23 | B24: Map 13 | C24: The Redwood Deep | D24: Old forest | E24: Bears, stags, fawns, boars, badgers, lynx, foxes | F24: Rage, Cleave | G24: King Slayer, Friction | H24: Boars and badgers rage; bears and boars sweep. | I24: Recommended had Guardian + Rage; Guardian now on Map 4. | J24: Rage, Friction, King Slayer
A25: 24 | B25: Map 14 | C25: Savanna Reaches | D25: Grassland (savanna) | E25: Zebras, giraffes, cheetahs, hyenas, elephants, rhinos, termites, monitors | F25: Stampede, Siege | G25: Rabid (one-off) | H25: The herd tramples through; the rhino breaks walls. | I25: Recommended had Pack/Pack Leader here; Pack moves to the wolves (Maps 16-17). | J25: Rabid, weakness, Stampede, Siege
A26: 25 | B26: Map 14 side | C26: The Canopy | D26: Rainforest | E26: Toucans, jaguars, dart frogs, monkeys, sloths, vines, rafflesia | F26: (none new) | G26: Banana, Bananarang, Durian (one-offs) | H26: The monkeys' one-offs live where monkeys live. | I26: Recommended had Boomerang; Boomerang stays with the Otter cards. | J26: Bananarang, Durian, Banana, Bulwark
A27: 26 | B27: Map 15 | C27: The Long Grass | D27: Farmland | E27: Horses, farm dogs, cats, mice, raccoons, stoats, owls, village militia | F27: Stealth, Backstab | G27: Loyal, Rally, Shield Call, Coffee (one-off) | H27: Raccoons hide in tall grass; stoats strike from behind; dogs keep faith. | I27: Recommended had Stealth + Pounce; Pounce is already Map 3. | J27: nocturnalHp, Coffee, Loyal, loyalGrant, rally, Shield Call
A28: 27 | B28: Map 16 | C28: The Pinewood Taiga | D28: Boreal forest | E28: Wolves, lynx, elk, snowshoe hares, wolverines, trickster foxes, pinecones | F28: Pack, Moonborn | G28: Pack Leader (the Howling Alpha), Explode (pinecone), Timber | H28: "The first of the wolf packs" (your blurb). Wolves howl at the moon. | I28: Recommended had Frostbite + Ice Arrow here; frost goes to the tundra. | J28: Pack, Moonborn, Pack Leader
A29: 28 | B29: Map 17 | C29: Wolfsbane Tundra | D29: Tundra | E29: Arctic wolves, foxes, ermine, musk oxen, mammoths, wolverines, yaks, snow owls | F29: Frostbite, Lone Wolf, Freeze | H29: "The packs here hunt in formation" (your blurb). | I29: Same Freeze and Lone Wolf; adds Frostbite from Map 16. | J29: Frostbite, Lone Wolf, freeze
A30: 29 | B30: Map 17 side | C30: The Ice Hollow | D30: Tundra (ice cave) | E30: Frost lynx, ermine, yaks, the ape-king | F30: (none new) | H30: Reuse. | I30: Same (nothing new).
A31: 30 | B31: Map 0 side | C31: The Old Bramble | D31: Old forest | E31: Hoglets, the bramble wall, an Ent, the forest's worst | F31: Counterattack | G31: Spiteful | H31: It unlocks late (after the Ice Hollow): an exam on everything, with a thorn wall that hits back. | I31: Recommended had Thorns here; Thorns is Map 1 now. | J31: Counterattack, Spiteful
A32: 31 | B32: Map 18 | C32: The Glass Dunes | D32: Desert | E32: Jackals, fennecs, meerkats, thorny devils, scorpions, widows, rocs, frillnecks, komodos | F32: Dry, Swift | G32: Sociable, Fencing, Tornado (one-off) | H32: Desert animals shrug off heat and strike first. | I32: Recommended had Dry + Fire Bolt; Fire waits for the volcano. | J32: Dry, Swift, Sociable, Tornado, Fencing
A33: 32 | B33: Map 19 | C33: Ashen Spurn | D33: Volcanic (ash ridge) | E33: Cinder geckos, ember centipedes, ash moths, salamanders, ember jackals, basalt boars, yetis | F33: Fire Arrow, Frenzy | G33: Scare, Immolation | H33: Fire meets the last of the snow; the yeti makes its stand. | I33: Same Fire Arrow; Frenzy instead of Immolation (Immolation goes to the Foundry). | J33: Fire Arrow, Frenzy, grit
A34: 33 | B34: Map 19 side | C34: Basalt Foundry | D34: Volcanic | E34: Magma titans, cinder hornets, stokers, vent crabs | F34: Immolation, Stun | G34: Grit | H34: The forge glows from inside. | I34: Recommended had Siege + Helmet; the Devil/Imp line is parked for 50+. | J34: scar, Immolation, Stun
A35: 34 | B35: Map 20 | C35: The Sundered Peak | D35: Mountain peak (apex) | E35: Apex animals of every biome: bears, gorillas, panthers, goats, cave bears, lions | F35: Bludgeon, Landslide | G35: Stagger, Lightning | H35: The last approach: the heaviest hitters, and rockslides. | I35: Same Landslide; Bludgeon instead of Lightning (Lightning is a maybe from Map 11). | J35: Bludgeon, Landslide, stagger, Dictator
A36: 35 | B36: Map 20 side | C36: Eye of the Volcano | D36: Volcanic (crater) | E36: Crater life: geckos, centipedes, condors, vent crabs, an ember wisp, the Contradiction | F36: (none new) | H36: "The living learned not to need much": extremophiles, not undead. | I36: The undead line (ghouls, skeletons, wraiths, liches) is parked for Map 50+.
A37: 36 | B37: Map 20 side | C37: Volcano Lair | D37: Volcanic (lair) | E37: The Caldera Wyrm and its court | F37: (none new) | G37: Pierce | H37: The world boss. | I37: Fire Drake Hatchling parked (a Dragon before Map 50). | J37: Pierce
A38: 37 | B38: Map 21 | C38: The Quiet Summit | D38: Mountain summit | E38: Snow owls, yaks, eagles, goats, the summit shrine's birds | F38: Worship, Prayer | G38: Divine Retribution, Avalanche (one-off) | H38: A shrine above the clouds: the faith skills (not magic). | I38: Recommended had Fencing + Counterattack; Fencing is a desert maybe, Counterattack is the Old Bramble. | J38: Worship, Prayer, Divine Retribution
B39: Maps 22-49 | C39: (plan) | D39: Special, still no magic | E39: Rainforest main map (the Canopy pool), Abyssal Plains (Map 29), Floodplains | F39: Eclipse, Floodplains, Twilight | G39: Pack Leader on lions, Syzygy (35+) | H39: Your road plan: more fights, terrain, a bit more advanced.
B40: Maps 50+ | C40: (plan) | D40: Magic and weird | E40: Dragons, the Devil/Imp line, the undead, phoenixes | F40: Magic, Ghost, Shade, Shadow, Supreme | G40: Irradiated, Psychic, Ichor, Wither | H40: Your rule: no magic before 50. The Basalt Foundry devils and the Eye of the Volcano undead wait here.
...

Sheet Cards per map count
A1: Map | B1: Map name | C1: Biome | D1: Fights (proposed) | E1: Fights today | F1: Unique enemy cards | G1: New to the player here | H1: Reused (seen before) | I1: In packs | J1: Not in packs (map rewards, base, new) | K1: Only on this map | L1: Elite-boss only | M1: Submap uniques | N1: New card concepts | O1: Today: unique enemy cards | P1: Change vs today
A2: Map 0 side | B2: Tutorial | C2: Forest edge | D2: 5 | E2: 5 | F2: =COUNTIFS(Placement!$C:$C,$B2) -> 12 | G2: =COUNTIFS(Placement!$C:$C,$B2,Placement!$L:$L,"Yes") -> 12 | H2: =F2-G2 -> 0 | I2: =COUNTIFS(Placement!$C:$C,$B2,Placement!$M:$M,"Yes") -> 0 | J2: =F2-I2 -> 12 | K2: =COUNTIFS(Placement!$C:$C,$B2,Placement!$N:$N,1) -> 0 | L2: =COUNTIFS(Placement!$C:$C,$B2,Placement!$I:$I,"elite-boss only") -> 0 | M2: =COUNTIFS(Placement!$C:$C,$B2,Placement!$I:$I,"submap unique") -> 0 | N2: =COUNTIFS(Placement!$C:$C,$B2,Placement!$K:$K,"new card (to design)") -> 0 | O2: 21 | P2: =F2-O2 -> -9
A3: Map 0 | B3: Bramblewood Outskirts | C3: Forest edge | D3: 4 | E3: 4 | F3: =COUNTIFS(Placement!$C:$C,$B3) -> 18 | G3: =COUNTIFS(Placement!$C:$C,$B3,Placement!$L:$L,"Yes") -> 6 | H3: =F3-G3 -> 12 | I3: =COUNTIFS(Placement!$C:$C,$B3,Placement!$M:$M,"Yes") -> 1 | J3: =F3-I3 -> 17 | K3: =COUNTIFS(Placement!$C:$C,$B3,Placement!$N:$N,1) -> 2 | L3: =COUNTIFS(Placement!$C:$C,$B3,Placement!$I:$I,"elite-boss only") -> 1 | M3: =COUNTIFS(Placement!$C:$C,$B3,Placement!$I:$I,"submap unique") -> 0 | N3: =COUNTIFS(Placement!$C:$C,$B3,Placement!$K:$K,"new card (to design)") -> 0 | O3: 20 | P3: =F3-O3 -> -2
A4: Map 1 | B4: Thistlewood | C4: Hedgerow & meadow | D4: 5 | E4: 5 | F4: =COUNTIFS(Placement!$C:$C,$B4) -> 13 | G4: =COUNTIFS(Placement!$C:$C,$B4,Placement!$L:$L,"Yes") -> 12 | H4: =F4-G4 -> 1 | I4: =COUNTIFS(Placement!$C:$C,$B4,Placement!$M:$M,"Yes") -> 1 | J4: =F4-I4 -> 12 | K4: =COUNTIFS(Placement!$C:$C,$B4,Placement!$N:$N,1) -> 6 | L4: =COUNTIFS(Placement!$C:$C,$B4,Placement!$I:$I,"elite-boss only") -> 2 | M4: =COUNTIFS(Placement!$C:$C,$B4,Placement!$I:$I,"submap unique") -> 0 | N4: =COUNTIFS(Placement!$C:$C,$B4,Placement!$K:$K,"new card (to design)") -> 0 | O4: 14 | P4: =F4-O4 -> -1
A5: Map 1 side | B5: Clovermead | C5: Hedgerow & meadow | D5: 4 | E5: 5 | F5: =COUNTIFS(Placement!$C:$C,$B5) -> 11 | G5: =COUNTIFS(Placement!$C:$C,$B5,Placement!$L:$L,"Yes") -> 3 | H5: =F5-G5 -> 8 | I5: =COUNTIFS(Placement!$C:$C,$B5,Placement!$M:$M,"Yes") -> 0 | J5: =F5-I5 -> 11 | K5: =COUNTIFS(Placement!$C:$C,$B5,Placement!$N:$N,1) -> 3 | L5: =COUNTIFS(Placement!$C:$C,$B5,Placement!$I:$I,"elite-boss only") -> 1 | M5: =COUNTIFS(Placement!$C:$C,$B5,Placement!$I:$I,"submap unique") -> 2 | N5: =COUNTIFS(Placement!$C:$C,$B5,Placement!$K:$K,"new card (to design)") -> 0 | O5: 20 | P5: =F5-O5 -> -9
A6: Map 2 | B6: Pebble Beach | C6: Shore | D6: 5 | E6: 5 | F6: =COUNTIFS(Placement!$C:$C,$B6) -> 11 | G6: =COUNTIFS(Placement!$C:$C,$B6,Placement!$L:$L,"Yes") -> 11 | H6: =F6-G6 -> 0 | I6: =COUNTIFS(Placement!$C:$C,$B6,Placement!$M:$M,"Yes") -> 3 | J6: =F6-I6 -> 8 | K6: =COUNTIFS(Placement!$C:$C,$B6,Placement!$N:$N,1) -> 3 | L6: =COUNTIFS(Placement!$C:$C,$B6,Placement!$I:$I,"elite-boss only") -> 3 | M6: =COUNTIFS(Placement!$C:$C,$B6,Placement!$I:$I,"submap unique") -> 0 | N6: =COUNTIFS(Placement!$C:$C,$B6,Placement!$K:$K,"new card (to design)") -> 0 | O6: 8 | P6: =F6-O6 -> 3
A7: Map 2 side | B7: Lilypad Reach | C7: Freshwater | D7: 4 | E7: 7 | F7: =COUNTIFS(Placement!$C:$C,$B7) -> 10 | G7: =COUNTIFS(Placement!$C:$C,$B7,Placement!$L:$L,"Yes") -> 6 | H7: =F7-G7 -> 4 | I7: =COUNTIFS(Placement!$C:$C,$B7,Placement!$M:$M,"Yes") -> 0 | J7: =F7-I7 -> 10 | K7: =COUNTIFS(Placement!$C:$C,$B7,Placement!$N:$N,1) -> 5 | L7: =COUNTIFS(Placement!$C:$C,$B7,Placement!$I:$I,"elite-boss only") -> 1 | M7: =COUNTIFS(Placement!$C:$C,$B7,Placement!$I:$I,"submap unique") -> 2 | N7: =COUNTIFS(Placement!$C:$C,$B7,Placement!$K:$K,"new card (to design)") -> 0 | O7: 20 | P7: =F7-O7 -> -10
A8: Map 2 side | B8: Smugglers' Grotto | C8: Sea cave | D8: 4 | E8: 4 | F8: =COUNTIFS(Placement!$C:$C,$B8) -> 9 | G8: =COUNTIFS(Placement!$C:$C,$B8,Placement!$L:$L,"Yes") -> 3 | H8: =F8-G8 -> 6 | I8: =COUNTIFS(Placement!$C:$C,$B8,Placement!$M:$M,"Yes") -> 3 | J8: =F8-I8 -> 6 | K8: =COUNTIFS(Placement!$C:$C,$B8,Placement!$N:$N,1) -> 2 | L8: =COUNTIFS(Placement!$C:$C,$B8,Placement!$I:$I,"elite-boss only") -> 0 | M8: =COUNTIFS(Placement!$C:$C,$B8,Placement!$I:$I,"submap unique") -> 2 | N8: =COUNTIFS(Placement!$C:$C,$B8,Placement!$K:$K,"new card (to design)") -> 0 | O8: 9 | P8: =F8-O8 -> 0
A9: Map 3 | B9: Gannet Cliffs | C9: Sea cliffs | D9: 6 | E9: 7 | F9: =COUNTIFS(Placement!$C:$C,$B9) -> 14 | G9: =COUNTIFS(Placement!$C:$C,$B9,Placement!$L:$L,"Yes") -> 11 | H9: =F9-G9 -> 3 | I9: =COUNTIFS(Placement!$C:$C,$B9,Placement!$M:$M,"Yes") -> 0 | J9: =F9-I9 -> 14 | K9: =COUNTIFS(Placement!$C:$C,$B9,Placement!$N:$N,1) -> 7 | L9: =COUNTIFS(Placement!$C:$C,$B9,Placement!$I:$I,"elite-boss only") -> 4 | M9: =COUNTIFS(Placement!$C:$C,$B9,Placement!$I:$I,"submap unique") -> 0 | N9: =COUNTIFS(Placement!$C:$C,$B9,Placement!$K:$K,"new card (to design)") -> 3 | O9: 13 | P9: =F9-O9 -> 1
A10: Map 4 | B10: Sunken Hollow | C10: Freshwater lowland | D10: 6 | E10: 5 | F10: =COUNTIFS(Placement!$C:$C,$B10) -> 16 | G10: =COUNTIFS(Placement!$C:$C,$B10,Placement!$L:$L,"Yes") -> 15 | H10: =F10-G10 -> 1 | I10: =COUNTIFS(Placement!$C:$C,$B10,Placement!$M:$M,"Yes") -> 4 | J10: =F10-I10 -> 12 | K10: =COUNTIFS(Placement!$C:$C,$B10,Placement!$N:$N,1) -> 14 | L10: =COUNTIFS(Placement!$C:$C,$B10,Placement!$I:$I,"elite-boss only") -> 5 | M10: =COUNTIFS(Placement!$C:$C,$B10,Placement!$I:$I,"submap unique") -> 0 | N10: =COUNTIFS(Placement!$C:$C,$B10,Placement!$K:$K,"new card (to design)") -> 0 | O10: 8 | P10: =F10-O10 -> 8
A11: Map 5 | B11: Gatorback Swamp | C11: Swamp | D11: 6 | E11: 7 | F11: =COUNTIFS(Placement!$C:$C,$B11) -> 14 | G11: =COUNTIFS(Placement!$C:$C,$B11,Placement!$L:$L,"Yes") -> 14 | H11: =F11-G11 -> 0 | I11: =COUNTIFS(Placement!$C:$C,$B11,Placement!$M:$M,"Yes") -> 1 | J11: =F11-I11 -> 13 | K11: =COUNTIFS(Placement!$C:$C,$B11,Placement!$N:$N,1) -> 7 | L11: =COUNTIFS(Placement!$C:$C,$B11,Placement!$I:$I,"elite-boss only") -> 3 | M11: =COUNTIFS(Placement!$C:$C,$B11,Placement!$I:$I,"submap unique") -> 0 | N11: =COUNTIFS(Placement!$C:$C,$B11,Placement!$K:$K,"new card (to design)") -> 0 | O11: 12 | P11: =F11-O11 -> 2
A12: Map 5 side | B12: The Sunken Grove | C12: Swamp | D12: 4 | E12: 4 | F12: =COUNTIFS(Placement!$C:$C,$B12) -> 9 | G12: =COUNTIFS(Placement!$C:$C,$B12,Placement!$L:$L,"Yes") -> 2 | H12: =F12-G12 -> 7 | I12: =COUNTIFS(Placement!$C:$C,$B12,Placement!$M:$M,"Yes") -> 0 | J12: =F12-I12 -> 9 | K12: =COUNTIFS(Placement!$C:$C,$B12,Placement!$N:$N,1) -> 2 | L12: =COUNTIFS(Placement!$C:$C,$B12,Placement!$I:$I,"elite-boss only") -> 0 | M12: =COUNTIFS(Placement!$C:$C,$B12,Placement!$I:$I,"submap unique") -> 2 | N12: =COUNTIFS(Placement!$C:$C,$B12,Placement!$K:$K,"new card (to design)") -> 0 | O12: 10 | P12: =F12-O12 -> -1
A13: Map 6 | B13: Sable Swampmire | C13: Swamp (night) | D13: 6 | E13: 8 | F13: =COUNTIFS(Placement!$C:$C,$B13) -> 14 | G13: =COUNTIFS(Placement!$C:$C,$B13,Placement!$L:$L,"Yes") -> 12 | H13: =F13-G13 -> 2 | I13: =COUNTIFS(Placement!$C:$C,$B13,Placement!$M:$M,"Yes") -> 0 | J13: =F13-I13 -> 14 | K13: =COUNTIFS(Placement!$C:$C,$B13,Placement!$N:$N,1) -> 12 | L13: =COUNTIFS(Placement!$C:$C,$B13,Placement!$I:$I,"elite-boss only") -> 4 | M13: =COUNTIFS(Placement!$C:$C,$B13,Placement!$I:$I,"submap unique") -> 0 | N13: =COUNTIFS(Placement!$C:$C,$B13,Placement!$K:$K,"new card (to design)") -> 0 | O13: 15 | P13: =F13-O13 -> -1
... A38: Map 21 | B38: The Quiet Summit | C38: Mountain summit | D38: 9 | E38: 6 | F38: =COUNTIFS(Placement!$C:$C,$B38) -> 16 | G38: =COUNTIFS(Placement!$C:$C,$B38,Placement!$L:$L,"Yes") -> 6 | H38: =F38-G38 -> 10 | I38: =COUNTIFS(Placement!$C:$C,$B38,Placement!$M:$M,"Yes") -> 1 | J38: =F38-I38 -> 15 | K38: =COUNTIFS(Placement!$C:$C,$B38,Placement!$N:$N,1) -> 6 | L38: =COUNTIFS(Placement!$C:$C,$B38,Placement!$I:$I,"elite-boss only") -> 2 | M38: =COUNTIFS(Placement!$C:$C,$B38,Placement!$I:$I,"submap unique") -> 0 | N38: =COUNTIFS(Placement!$C:$C,$B38,Placement!$K:$K,"new card (to design)") -> 0 | O38: 15 | P38: =F38-O38 -> 1
A39: Total | B39: Sum of rows (a card on several maps counts once per map) | D39: =SUM(D2:D38) -> 217 | E39: =SUM(E2:E38) -> 232 | F39: =SUM(F2:F38) -> 472 | G39: =SUM(G2:G38) -> 339 | H39: =SUM(H2:H38) -> 133 | I39: =SUM(I2:I38) -> 60 | J39: =SUM(J2:J38) -> 412 | K39: =SUM(K2:K38) -> 243 | ... P39: =SUM(P2:P38) -> -19
A40: Distinct | B40: Distinct enemy cards in the whole proposal | F40: 339 | N40: 6 | O40: 244

Sheet Biome supply vs need
A1: Biome family | B1: Maps that use it (proposal) | C1: Main maps | D1: Side maps | E1: Cards that exist (eligible enemies) | F1: Placed in this proposal | G1: Not placed | H1: Cards the plan needs (8 per main map + 2 per side map) | I1: Surplus (+) / gap (-) | J1: Verdict | K1: Not placed (names)
A2: Woodland & hedgerow | B2: Tutorial, Bramblewood Outskirts, Thistlewood, Clovermead, The Briar Maze, The Redwood Deep, The Old Bramble | C2: 4 | D2: 3 | E2: 79 | F2: 66 | G2: =E2-F2 -> 13 | H2: =C2*8+D2*2 -> 38 | I2: =E2-H2 -> 41 | J2: Surplus. The biggest pool: rabbits, chipmunks, mice, foxes, bears, deer, boars. Fine, it covers 7 maps. | K2: Buck Brawler, Chipmunk Cavalry, Courier Pigeon, Feral Tuskboar, Fox Warchief, Great Horned Owl, Jackrabbit Sprinter, Owl Nightwatch, Pack Rat Looter, Raccoon Bandit, Raccoon Warlord, Raven Hexcaller, Sparrow Chick
A3: Player factions (Otter, Hummingbird) | B3: (none before Map 22) | C3: 0 | D3: 0 | E3: 50 | F3: 3 | G3: =E3-F3 -> 47 | H3: =C3*8+D3*2 -> 0 | I3: =E3-H3 -> 50 | J3: Not enemy stock; a few Otter commons appear as Legion outposts (Maps 2, 9). | K3: Cobalt Fledgling, Cobalt Talon Skirmisher, Crimson Recruit, Crimson Wing Duelist Cadet, Daily Post, Dawn Bellringer, Dominion Nestguard, Fleetfoot'd, Gold-throated Acolyte, Helmeted Otter, Honeyjoe Brewer, Hummingbird Needler, Hush-Wing Spy, Lantern Bearer, Marshal of Rivergate, Mosswing, Nectar Sipper, Nectar Vintner, Net Thrower, Optio of the Ford, Otter Centurion, Otter Ferryman, Otter Flag Bearer, Otter Guard, Otter Kit, Otter Lantern Bearer, Otter Netmender, Otter Paddler, Otter Scout, Otter Shieldback, Petal Fletcher, River Warden, Riverbed Diver, Rivergate Recruit, Rivergate Tribune, Riverstone Slinger, Riverwing Envoy, Royal Guard, Ruby-Throat Duelist, Shellwright Apprentice, Sunfeather Scout, Sunspire Choirmother, Sunspire Envoy, Sunspire Sky-Sovereign, Sunthroat Courier, Violet Vane Fletcher, Voidfeather Scout
A4: Undergrowth & fungi | B4: The Morel Hollow, The Mycelium Deep | C4: 1 | D4: 1 | E4: 42 | F4: 29 | G4: =E4-F4 -> 13 | H4: =C4*8+D4*2 -> 10 | I4: =E4-H4 -> 32 | J4: Surplus of bugs (bees, ants, beetles) once the player-side bees and ants are counted. | K4: Ant Hill, Ant Warrior, Bee Drone, Bee Forager, Bee Knight, Bee Sentry, Colony, Elder Willow, Monarch Wingblade, Nest, Soldier Ant, Swarm Matriarch, Tunnel Ant
A5: Freshwater | B5: Lilypad Reach, Sunken Hollow | C5: 1 | D5: 1 | E5: 34 | F5: 27 | G5: =E5-F5 -> 7 | H5: =C5*8+D5*2 -> 10 | I5: =E5-H5 -> 24 | J5: About right. The beaver lodge moved to Map 4 gives it a real home. | K5: Camouflage Frog, Duckling Squadron, Guppy, Migration Leader, Old Willow of the Ford, Poison Dart Croaker, Silver Minnow
A6: Late (50+: dragons, magic, undead, devils) | B6: (none before Map 22) | C6: 0 | D6: 0 | E6: 31 | F6: 1 | G6: =E6-F6 -> 30 | H6: =C6*8+D6*2 -> 0 | I6: =E6-H6 -> 31 | J6: Parked: dragons, the Devil/Imp line, undead, irradiated, divine. Not needed before Map 50. | K6: Ash Imp, Ashbone Ghoul, Black Dragon, Blackmass Acolyte, Blessed Avatar, Blue Dragon, Brimstone Hound, Cinder Imp, Cinder Skeleton, Dread Bell, Ember Revenant, Fire Drake Hatchling, Green Dragon, Irradiated Axolotl, Irradiated Couatl, Irradiated Glow Wyrm, Lurking Dread, Magma Wraith, Obsidian Lich, Phoenix Fledgling, Pit Glutton, Puppeteer Imp, Red Dragon, Shrine Acolyte, Shrine Bell-Ringer, Shrine High Priest, The Sixfold, Tithe Collector, Tunnel Wyrm, White Dragon
A7: Underground | B7: Smugglers' Grotto, Caves & Alcoves, The Glimmer Depths | C7: 1 | D7: 2 | E7: 30 | F7: 25 | G7: =E7-F7 -> 5 | H7: =C7*8+D7*2 -> 12 | I7: =E7-H7 -> 18 | J7: Right-sized; the electric bats finally have a home. | K7: Glowworm Cluster, Millipede Hauler, Quarry Troll, Tiny Cave Dweller, Upside-Down Bat
A8: Swamp | B8: Gatorback Swamp, The Sunken Grove, Sable Swampmire | C8: 2 | D8: 1 | E8: 29 | F8: 27 | G8: =E8-F8 -> 2 | H8: =C8*8+D8*2 -> 18 | I8: =E8-H8 -> 11 | J8: Right-sized for 3 maps. | K8: Skull Vulture, Turtle Bastion
A9: Boreal & tundra | B9: The Pinewood Taiga, Wolfsbane Tundra, The Ice Hollow | C9: 2 | D9: 1 | E9: 28 | F9: 27 | G9: =E9-F9 -> 1 | H9: =C9*8+D9*2 -> 18 | I9: =E9-H9 -> 10 | J9: About right; wolves need Pack and Pack Leader on the sheet. | K9: Ironmaw Warwolf
A10: Farm & village | B10: The Long Grass | C10: 1 | D10: 0 | E10: 28 | F10: 22 | G10: =E10-F10 -> 6 | H10: =C10*8+D10*2 -> 8 | I10: =E10-H10 -> 20 | J10: Surplus (pack-heavy). Long Grass uses about 20; the rest are pack and reward cards. | K10: Crown Pretender, Meerkat Wayfarer, Pigeon Peon, Shepherd, Tomcat, Weredog
A11: Sea | B11: Coral Current, The Sunken Depths | C11: 1 | D11: 1 | E11: 27 | F11: 22 | G11: =E11-F11 -> 5 | H11: =C11*8+D11*2 -> 10 | I11: =E11-H11 -> 17 | J11: Surplus: whales, sharks, squid, jellies, raid squid. Enough for a second sea map in 22-40 (the Abyssal Plains, Map 29). | K11: Abyss Lantern Squid, Goliath Broodmother, Goliath Tentacle, Lion's Mane Jelly, Vampire Squid
A12: Mountain | B12: Eyrie Heights, The Aerie Vault, The Sundered Peak, The Quiet Summit | C12: 3 | D12: 1 | E12: 23 | F12: 19 | G12: =E12-F12 -> 4 | H12: =C12*8+D12*2 -> 26 | I12: =E12-H12 -> -3 | J12: Thin at the low end: no Volley or Twin Shot carrier (Chough Flock, Kestrel), no baby (Eaglet). | K12: Abbey Goose, Friar Badger, Golden Magpie, Mirrorhide Mutant
A13: Other (structures, elementals, oddities) | B13: (none before Map 22) | C13: 0 | D13: 0 | E13: 18 | F13: 9 | G13: =E13-F13 -> 9 | H13: =C13*8+D13*2 -> 0 | I13: =E13-H13 -> 18 | J13: Golems, wisps, changelings, pack oddities. | K13: Gale Sprite, Glass Changeling, Glass Golem, Iron Warden, Sergeant Bramblefox, Snail Mail, Stoneheart Golem, Stormcaller, Two-Headed Calf
... A16: Rainforest | B16: The Canopy | C16: 0 | D16: 1 | E16: 12 | F16: 9 | G16: =E16-F16 -> 3 | H16: =C16*8+D16*2 -> 2 | I16: =E16-H16 -> 10 | J16: Surplus for a side map (about 14 cards on one 4-fight map). Candidate for a main map in 22-40. | K16: Canopy Sloth Guardian, Hanging Loafer, Old-Growth Tortoise
A17: Grassland | B17: Savanna Reaches | C17: 1 | D17: 0 | E17: 10 | F17: 10 | G17: =E17-F17 -> 0 | H17: =C17*8+D17*2 -> 8 | I17: =E17-H17 -> 2 | J17: Gap: 10 cards for an 8-fight map; no lions or wild dogs below boss level, no gazelle or warthog. Pack has no savanna carrier.
A18: Desert | B18: The Glass Dunes | C18: 1 | D18: 0 | E18: 10 | F18: 10 | G18: =E18-F18 -> 0 | H18: =C18*8+D18*2 -> 8 | I18: =E18-H18 -> 2 | J18: About right.
A19: Total | C19: =SUM(C2:C18) -> 22 | D19: =SUM(D2:D18) -> 15 | E19: =SUM(E2:E18) -> 479 | F19: =SUM(F2:F18) -> 332 | G19: =SUM(G2:G18) -> 147 | H19: =SUM(H2:H18) -> 206 | I19: =SUM(I2:I18) -> 273
A21: Eligible = not test, token, materia, equipment, spell, field, egg, leader or dummy. Families come from each card's archetypes and species, so a few cards sit in a neighbouring family (placed cards still count where they come from, not where they are placed). "Needs" is a rule of thumb: about 8 natives per main map and 2 per side map, before reuse.

Sheet Babies & eggs
A1: Kind | B1: Card id | C1: Name | D1: Rarity (sheet) | E1: Hatches into / species | F1: Where today | G1: Where in this proposal | H1: Proposal
A2: Egg | B2: egg-woodland | C2: Woodland Egg | D2: Common | E2: anything | F2: source: nest | G2: (Nest, Map 4) | H2: Keep. This is your generic "Green egg": hatches anything. Consider renaming it Green Egg.
A3: Egg | B3: egg-bird | C3: Speckled Egg | D3: Uncommon | E3: Bird | F3: source: nest | G3: (Nest, Map 4) | H3: Keep: any bird.
A4: Egg | B4: egg-scaly | C4: Leathery Egg | D4: Uncommon | E4: Reptile, Amphibian | F4: source: nest | G4: (Nest, Map 4) | H4: Keep: any reptile or amphibian.
A5: Egg | B5: egg-bug | C5: Cocoon | D5: Uncommon | E5: Insect, Arachnid | F5: source: nest | G5: (Nest, Map 4) | H5: Keep: any insect or spider.
A6: Egg | B6: egg-water | C6: Roe Pearl | D6: Uncommon | E6: Fish, Cetacean, Mollusc, Crustacean | F6: source: nest | G6: (Nest, Map 4) | H6: Keep: any fish, whale, mollusc or crab.
A7: Egg | B7: egg-beast | C7: Den Bundle | D7: Uncommon | E7: Canid, Felid, Ursid, Cervid, Suid, Rodent, Lagomorph, Equid, Bovine, Primate, Mammal, Megafauna, Feline, Procyonid, Mustelid, Erinaceid, Herpestid, Hyaenid, Xenarthran, Bat, Pinniped, Cetacean | F7: source: nest | G7: (Nest, Map 4) | H7: Keep: this is the "mammal den bundle" (any mammal, Mustelids included).
A8: Egg | B8: egg-otter | C8: River Bundle | D8: Uncommon | E8: Mustelid | F8: source: nest | G8: (Nest, Map 4) | H8: The only species-specific egg (Otters only). Retire it into the Den Bundle, or widen it to any River card.
A9: Egg | B9: egg-red-dragon | C9: Red Dragon Egg | D9: Legendary | E9: red-dragon | F9: nowhere (no map, no source) | G9: (crafted, Map 50+) | H9: Keep as the deliberate exception: dragons can only be crafted from their egg (Map 50+).
A10: Baby | B10: otter-kit | C10: Otter Kit | D10: Starter | E10: Mustelid | F10: on The Old Bramble (Map 0 side), Tutorial (Map 0 side) | G10: (not placed) | H10: Keep: Otter starter basic (player side).
A11: Baby | B11: cobalt-talon-fledgling | C11: Cobalt Fledgling | D11: Starter | E11: Bird | F11: nowhere (no map, no source) | G11: (not placed) | H11: Keep: Hummingbird starter basic (player side).
A12: Baby | B12: fox-kit | C12: Fox Kit | D12: Rare | E12: Canid | F12: on Map 0, Map 1, Map 13 | G12: Bramblewood Outskirts, The Redwood Deep | H12: Relabel Uncommon. The 0-4 uncommon; reappears on Map 13.
... A36: Baby (token) | B36: maggot-swarmling | C36: Maggot | D36: (none) | E36: Insect | F36: nowhere (no map, no source) | G36: (not placed) | H36: Keep: token.
A37: Missing baby (yes) | B37: (new) | C37: Wolf Pup | D37: Common | E37: Canid | H37: Maps 16-17: the first wolf packs need a cheap body that joins the Pack chain.
A38: Missing baby (yes) | B38: (new) | C38: Eaglet | D38: Common | E38: Bird | H38: Map 11 and the Aerie Vault ("the oldest nests"): the mountain has no young at all.
A39: Missing baby (maybe) | B39: (new) | C39: Seal Pup | D39: Common | E39: Pinniped | H39: Map 17 coast or Map 3 cliff foot; only if you want a third.
A40: Not needed | B40: (new) | C40: Lion Cub | D40: - | E40: Felid | H40: Pride Queen and the Triumvirate carry the lions; a cub adds little.
A41: Not needed | B41: (new) | C41: Tadpole | D41: - | E41: Amphibian | H41: Shallows Fry and the Duckling already cover "baby in the water".
A42: Missing egg | C42: (none) | D42: - | E42: - | H42: Six generic eggs (Green/Woodland, Speckled, Leathery, Cocoon, Roe Pearl, Den Bundle) cover every family. Add none; retire River Bundle.
